Workbook

Sheet Cases
A1: =-2^2 -> 4
A2: =2^3^2 -> 64
A3: =-Data!A4^2 -> 0.002601
A4: =2^-1 -> 0.5
A5: =1+2*3-4/2 -> 5
A6: =(1+2)*3 -> 9
A7: =10-2-3 -> 5
A8: =2*-3 -> -6
A9: =-(2^2) -> -4
A10: =1+2&"x" -> 3x
A11: ="a"&1.5 -> a1.5
A12: ="<="&0.25 -> <=0.25
A13: =1/3&"" -> 0.333333333333333
A14: ="<="&Data!D1 -> <=-0.0123456789012346
A15: =1+2<4 -> TRUE
A16: =1=1 -> TRUE
A17: ="a"="A" -> TRUE
A18: =2>=3 -> FALSE
A19: =1<>1 -> FALSE
A20: =TRUE+1 -> 2
A21: =Data!A1>0.01 -> TRUE
A22: =1/0 -> #DIV/0!
A23: =SQRT(-1) -> #NUM!
A24: =Data!$A$1+Data!A$2+Data!$A3 -> 0.011
A25: ='Other Data'!B2*2 -> 40
A26: =SUM('Other Data'!B1:B3) -> 60
A27: ='Other Data'!C1+1 -> 6.1
A28: =Data!$B$4*(1+Data!A4) -> 0.03153
A29: =SUM(Data!A1:A8) -> 0.06
A30: =SUM(Data!C1:C5) -> 9
A31: =AVERAGE(Data!A1:A8) -> 0.0075
A32: =AVERAGE(Data!C1:C5) -> 3
A33: =COUNT(Data!C1:C5) -> 3
A34: =COUNT(Data!A1:A8) -> 8
A35: =MIN(Data!A1:A8) -> -0.009
A36: =MAX(Data!A1:A8) -> 0.051
A37: =MAX(Data!A2,Data!A3) -> 0.003
A38: =MIN(Data!C2,Data!C3) -> -2
A39: =MAX(Data!E1:E3) -> 0
A40: =SQRT(2) -> 1.4142136
...

Sheet Data
A1: 0.012 | B1: 0.01 | C1: 4 | D1: -0.012345679
A2: -0.004 | B2: -0.006 | D2: -0.02
A3: 0.003 | B3: 0.001 | C3: -2 | D3: 0.01
A4: 0.051 | B4: 0.03 | C4: note | D4: -0.012345679
A5: -0.009 | B5: -0.012 | C5: 7
A6: 0.002 | B6: 0.004
A7: 0.006 | B7: 0.005
A8: -0.001 | B8: 0
A10: 0.25 | B10: 0.25 | C10: 0.3 | D10: 0.2
A11: 0.01 | B11: -0.02 | C11: 0.005 | D11: 0.03

Sheet Other Data
B1: 10 | C1: =Data!A4*100 -> 5.1
B2: 20
B3: 30
